<?xml version='1.0' encoding='utf-8'?>
<robot xmlns:xacro="http://www.ros.org/wiki/xacro" name="example">
    <xacro:arg name="robot_name" default=""/>
    <xacro:property name="namespace" value="$(arg robot_name)"/>
    <xacro:property name="description_package" value="balegce"/>
  
    <!-- Include all model properties-->
    <xacro:include filename="$(find ${description_package})/robot/visual/properties.xacro"/>
        
    <!-- Add manipulator -->
    <xacro:include filename="$(find ${description_package})/robot/visual/manipulator.xacro"/>
    <xacro:include filename="$(find ${description_package})/robot/visual/sensor.xacro"/>

    <xacro:property name="PI" value="3.141592653589793"/>

    <link name="world"/>
    <joint name="revoluteJoint_0" type="revolute">
            <origin xyz="0 0 0" rpy="0 0 0"/>
            <parent link="world"/>
            <child link="leg"/>
            <axis xyz="1 0 0"/>     
            <limit 
                lower="-$(PI/2)" 
                upper="$(PI/2)" 
                velocity="1000.0" 
                effort="1000.0"/>     
    </joint>
    
    <xacro:balegce/>
    <!-- attrach sensor -->

    <xacro:sensor_link/>


</robot>
